<?xml version="1.0"?>
<sdf version="1.6">
    <model name="{{ name }}">

        <!-- World pose -->
        <pose>-2.51 2.57 4.62 0 0 -1.92</pose>


        <link name="base_link">
            <inertial>
                <pose frame="">0.0 0.0 0.062 0 0 0</pose>
                <mass>46.034</mass>
                <inertia>
                    <ixx>0.613201</ixx>
                    <ixy>-0.0236401</ixy>
                    <ixz>-0.1197</ixz>
                    <iyy>1.7496</iyy>
                    <iyz>-0.00154411</iyz>
                    <izz>2.0406</izz>
                </inertia>
            </inertial>
            <collision name="base_link_collision">
                <pose frame="">0 0 0.15 0 0 0</pose>
                <geometry>
                    <box>
                        <size>0.925 0.38 0.21</size>
                    </box>
                </geometry>
            </collision>
            <collision name="base_link_collision_2">
                <pose frame="">0 0 0.035 0 0 0</pose>
                <geometry>
                    <box>
                        <size>0.154 0.627 0.07</size>
                    </box>
                </geometry>
            </collision>

            <visual name="base_link_visual">
                <pose frame="">0 0 0 0 0 0</pose>
                <geometry>
                    <mesh>
                        <uri>model://scoutv2/meshes/base_link.dae</uri>
                    </mesh>
                </geometry>
            </visual>


            <sensor name="imu_sensor" type="imu">
                <always_on>1</always_on>
                <update_rate>50</update_rate>
                <imu>
                    <enable_orientation>0</enable_orientation>
                    <angular_velocity>
                        <x>
                            <noise type="gaussian">
                                <mean>0</mean>
                                <stddev>0.009</stddev>
                                <bias_mean>0.00075</bias_mean>
                                <bias_stddev>0.005</bias_stddev>
                                <dynamic_bias_stddev>0.00002</dynamic_bias_stddev>
                                <dynamic_bias_correlation_time>400.0</dynamic_bias_correlation_time>
                                <precision>0.00025</precision>
                            </noise>
                        </x>
                        <y>
                            <noise type="gaussian">
                                <mean>0</mean>
                                <stddev>0.009</stddev>
                                <bias_mean>0.00075</bias_mean>
                                <bias_stddev>0.005</bias_stddev>
                                <dynamic_bias_stddev>0.00002</dynamic_bias_stddev>
                                <dynamic_bias_correlation_time>400.0</dynamic_bias_correlation_time>
                                <precision>0.00025</precision>
                            </noise>
                        </y>
                        <z>
                            <noise type="gaussian">
                                <mean>0</mean>
                                <stddev>0.009</stddev>
                                <bias_mean>0.00075</bias_mean>
                                <bias_stddev>0.005</bias_stddev>
                                <dynamic_bias_stddev>0.00002</dynamic_bias_stddev>
                                <dynamic_bias_correlation_time>400.0</dynamic_bias_correlation_time>
                                <precision>0.00025</precision>
                            </noise>
                        </z>
                    </angular_velocity>
                    <linear_acceleration>
                        <x>
                            <noise type="gaussian">
                                <mean>0</mean>
                                <stddev>0.021</stddev>
                                <bias_mean>0.05</bias_mean>
                                <bias_stddev>0.0075</bias_stddev>
                                <dynamic_bias_stddev>0.000375</dynamic_bias_stddev>
                                <dynamic_bias_correlation_time>175.0</dynamic_bias_correlation_time>
                                <precision>0.005</precision>
                            </noise>
                        </x>
                        <y>
                            <noise type="gaussian">
                                <mean>0</mean>
                                <stddev>0.021</stddev>
                                <bias_mean>0.05</bias_mean>
                                <bias_stddev>0.0075</bias_stddev>
                                <dynamic_bias_stddev>0.000375</dynamic_bias_stddev>
                                <dynamic_bias_correlation_time>175.0</dynamic_bias_correlation_time>
                                <precision>0.005</precision>
                            </noise>
                        </y>
                        <z>
                            <noise type="gaussian">
                                <mean>0</mean>
                                <stddev>0.021</stddev>
                                <bias_mean>0.05</bias_mean>
                                <bias_stddev>0.0075</bias_stddev>
                                <dynamic_bias_stddev>0.000375</dynamic_bias_stddev>
                                <dynamic_bias_correlation_time>175.0</dynamic_bias_correlation_time>
                                <precision>0.005</precision>
                            </noise>
                        </z>
                    </linear_acceleration>
                </imu>
            </sensor>



            <visual name="camera_visual">
                <pose>0.43 0 0.26 0 0 0</pose>
                <geometry>
                    <box>
                        <size>0.02 0.02 0.02</size>
                    </box>
                </geometry>
            </visual>
            <sensor name="camera_front" type="camera">
                <pose>0.43 0 0.26 0 0 0</pose>
                <always_on>1</always_on>
                <update_rate>20</update_rate>
                <camera name="camera_front">
                    <!--<cameraInfoTopicName>camera_info</cameraInfoTopicName>-->
                    <!--<hackBaseline>0.07</hackBaseline>-->
                    <horizontal_fov>1.0472</horizontal_fov>
                    <lens>
                        <intrinsics>
                          <!-- fx = fy = width / ( 2 * tan (hfov / 2 ) ) -->
                          <fx>277.1</fx>
                          <fy>277.1</fy>
                          <!-- cx = ( width + 1 ) / 2 -->
                          <cx>160.5</cx>
                          <!-- cy = ( height + 1 ) / 2 -->
                          <cy>120.5</cy>
                          <s>0</s>
                        </intrinsics>
                    </lens>
                    <distortion>
                        <k1>0.0</k1>
                        <k2>0.0</k2>
                        <k3>0.0</k3>
                        <p1>0.0</p1>
                        <p2>0.0</p2>
                        <center>0.5 0.5</center>
                    </distortion>
                    <image>
                        <width>320</width>
                        <height>240</height>
                        <format>R8G8B8</format>
                    </image>
                    <clip>
                        <near>0.01</near>
                        <far>300</far>
                    </clip>
                    <noise>
                        <type>gaussian</type>
                        <mean>0</mean>
                        <stddev>0.007</stddev>
                    </noise>
                </camera>
            </sensor>


            <sensor name="front_laser" type="gpu_ray">
                <pose>0.43 0 0.26 0 0 0</pose>
                <update_rate>20</update_rate>
                <lidar>
                    <scan>
                        <horizontal>
                            <samples>720</samples>
                            <resolution>1</resolution>
                            <min_angle>-2.3562</min_angle>
                            <max_angle>2.3562</max_angle>
                        </horizontal>
                    </scan>
                    <range>
                        <min>0.04</min>
                        <max>5</max>
                        <resolution>0.01</resolution>
                    </range>
                    <noise>
                        <type>gaussian</type>
                        <mean>0</mean>
                        <stddev>0.01</stddev>
                    </noise>
                </lidar>
            </sensor>
        </link>




        <link name="front_left_wheel">
            <pose frame="">0.249 0.29153 -0.0702 0 0 0</pose>
            <inertial>
                <mass>8</mass>
                <inertia>
                    <ixx>0.1171</ixx>
                    <ixy>0</ixy>
                    <ixz>0</ixz>
                    <iyy>0.1361</iyy>
                    <iyz>0</iyz>
                    <izz>0.1171</izz>
                </inertia>
            </inertial>
            <collision name="collision">
                <pose frame="">0 0 0 -1.5707963267948966 0 0</pose>
                <geometry>
                    <cylinder>
                        <length>1.1653e-01</length>
                        <radius>1.6459e-01</radius>
                    </cylinder>
                </geometry>
                <surface>
                    <friction>
                        <ode>
                            <mu>0.5</mu>
                            <mu2>1</mu2>
                            <slip1>0.00062</slip1>
                            <slip2>0</slip2>
                            <fdir1>0 0 1</fdir1>
                        </ode>
                    </friction>
                </surface>
            </collision>
            <visual name="visual">
                <geometry>
                    <mesh>
                        <uri>model://scoutv2/meshes/wheel_type2.dae</uri>
                    </mesh>
                </geometry>
            </visual>
        </link>
        <joint name="front_left_wheel_joint" type="revolute">
            <parent>base_link</parent>
            <child>front_left_wheel</child>
            <axis>
                <xyz>0 1 0</xyz>
                <limit>
                    <lower>-1.79769e+308</lower>
                    <upper>+1.79769e+308</upper>
                </limit>
            </axis>
        </joint>
        <link name="front_right_wheel">
            <pose frame="">0.249 -0.29153 -0.0702 0 0 0</pose>
            <inertial>
                <mass>8</mass>
                <inertia>                
                    <ixx>0.02467</ixx>
                    <ixy>0</ixy>
                    <ixz>0</ixz>
                    <iyy>0.04411</iyy>
                    <iyz>0</iyz>
                    <izz>0.02467</izz>
                </inertia>
            </inertial>
            <collision name="collision">
                <pose frame="">0 0 0 -1.5707963267948966 0 0</pose>
                <geometry>
                    <cylinder>
                        <length>0.11653</length>
                        <radius>0.16459</radius>
                    </cylinder>
                </geometry>
                <surface>
                    <friction>
                        <ode>
                            <mu>0.5</mu>
                            <mu2>1</mu2>
                            <slip1>0.00062</slip1>
                            <slip2>0</slip2>
                            <fdir1>0 0 1</fdir1>
                        </ode>
                    </friction>
                </surface>
            </collision>
            <visual name="visual">
                <geometry>
                    <mesh>
                        <uri>model://scoutv2/meshes/wheel_type2.dae</uri>
                    </mesh>
                </geometry>
            </visual>
        </link>
        <joint name="front_right_wheel_joint" type="revolute">
            <parent>base_link</parent>
            <child>front_right_wheel</child>            
            <axis>
                <xyz>0 1 0</xyz>
                <limit>
                    <lower>-1.79769e+308</lower>
                    <upper>+1.79769e+308</upper>
                </limit>
            </axis>
        </joint>
        <link name="rear_left_wheel">
            <pose frame="">-0.249 0.29153 -0.0702 0 0 0</pose>
            <inertial>
                <mass>8</mass>
                <inertia>
                    <ixx>0.02467</ixx>
                    <ixy>0</ixy>
                    <ixz>0</ixz>
                    <iyy>0.04411</iyy>
                    <iyz>0</iyz>
                    <izz>0.02467</izz>
                </inertia>
            </inertial>
            <collision name="collision">
                <pose frame="">0 0 0 -1.5707963267948966 0 0</pose>
                <geometry>
                    <cylinder>
                        <length>0.11653</length>
                        <radius>0.16459</radius>
                    </cylinder>
                </geometry>
                <surface>
                    <friction>
                        <ode>
                            <mu>0.5</mu>
                            <mu2>1</mu2>
                            <slip1>0.00062</slip1>
                            <slip2>0</slip2>
                            <fdir1>0 0 1</fdir1>
                        </ode>
                    </friction>
                </surface>
            </collision>
            <visual name="visual">
                <geometry>
                    <mesh>
                        <uri>model://scoutv2/meshes/wheel_type1.dae</uri>
                    </mesh>
                </geometry>
            </visual>
        </link>
        <joint name="rear_left_wheel_joint" type="revolute">
            <parent>base_link</parent>
            <child>rear_left_wheel</child>
            <axis>
                <xyz>0 1 0</xyz>
                <limit>
                    <lower>-1.79769e+308</lower>
                    <upper>+1.79769e+308</upper>
                </limit>
            </axis>
        </joint>
        <link name="rear_right_wheel">
            <pose frame="">-0.249 -0.29153 -0.0702 0 0 0</pose>
            <inertial>
                <mass>8</mass>
                <inertia>
                    <ixx>0.02467</ixx>
                    <ixy>0</ixy>
                    <ixz>0</ixz>
                    <iyy>0.04411</iyy>
                    <iyz>0</iyz>
                    <izz>0.02467</izz>
                </inertia>
            </inertial>
            <collision name="collision">
                <pose frame="">0 0 0 -1.5707963267948966 0 0</pose>
                <geometry>
                    <cylinder>
                        <length>0.11653</length>
                        <radius>0.16459</radius>
                    </cylinder>
                </geometry>
                <surface>
                    <friction>
                        <ode>
                            <mu>0.5</mu>
                            <mu2>1</mu2>
                            <slip1>0.00062</slip1>
                            <slip2>0</slip2>
                            <fdir1>0 0 1</fdir1>
                        </ode>
                    </friction>
                </surface>
            </collision>
            <visual name="visual">
                <geometry>
                    <mesh>
                        <uri>model://scoutv2/meshes/wheel_type1.dae</uri>
                    </mesh>
                </geometry>
            </visual>
        </link>
        <joint name="rear_right_wheel_joint" type="revolute">
            <parent>base_link</parent>
            <child>rear_right_wheel</child>            
            <axis>
                <xyz>0 1 0</xyz>
                <limit>
                    <lower>-1.79769e+308</lower>
                    <upper>+1.79769e+308</upper>
                </limit>
            </axis>
        </joint>

        <plugin
            filename="gz-sim-diff-drive-system"
            name="gz::sim::systems::DiffDrive">
            <left_joint>front_left_wheel_joint</left_joint>
            <left_joint>rear_left_wheel_joint</left_joint>
            <right_joint>front_right_wheel_joint</right_joint>
            <right_joint>rear_right_wheel_joint</right_joint>
            <wheel_separation>0.58</wheel_separation>
            <wheel_radius>0.165</wheel_radius>
            <max_linear_acceleration>1</max_linear_acceleration>
            <min_linear_acceleration>-1</min_linear_acceleration>
            <max_angular_acceleration>2</max_angular_acceleration>
            <min_angular_acceleration>-2</min_angular_acceleration>
            <max_linear_velocity>0.5</max_linear_velocity>
            <min_linear_velocity>-0.5</min_linear_velocity>
            <max_angular_velocity>1</max_angular_velocity>
            <min_angular_velocity>-1</min_angular_velocity>
        </plugin>

        <!-- <plugin name='gz::sim::systems::OdometryPublisher' filename='gz-sim-odometry-publisher-system'>
            <dimensions>3</dimensions>
            <odom_publish_frequency>10.0</odom_publish_frequency>
            <odom_frame> odom </odom_frame>
            <robot_base_frame> base_link </robot_base_frame>            
        </plugin> -->
        
        <plugin name='gz::sim::systems::PosePublisher' filename='libgz-sim-pose-publisher-system.so'>
            <publish_link_pose>true</publish_link_pose>
            <publish_sensor_pose>true</publish_sensor_pose>
            <publish_collision_pose>false</publish_collision_pose>
            <publish_visual_pose>false</publish_visual_pose>
            <publish_nested_model_pose>false</publish_nested_model_pose>
            <publish_model_pose>false</publish_model_pose>
            <use_pose_vector_msg>true</use_pose_vector_msg>
            <static_publisher>false</static_publisher>
            <static_update_frequency>30</static_update_frequency>
        </plugin>



        <joint name="os_sensor_mount_joint" type="fixed">        
            <parent> base_link </parent>
            <child> os_sensor </child>
        </joint>

        <joint name="os_sensor_mount_pole_joint" type="fixed">        
            <parent> base_link </parent>
            <child> os_sensor_pole </child>
        </joint>


        <link name="os_sensor">
            <pose frame="">0. -0. 0.50 0 0 0</pose>
            <inertial>
                <mass>0.33</mass>
                <pose frame=""> 0 0 0.365 0 0 0 </pose>
                <inertia>
                    <ixx>0.000241148</ixx>
                    <ixy>0 </ixy>
                    <ixz>0</ixz>
                    <iyy>0.000241148</iyy>
                    <iyz>0</iyz>
                    <izz>0.000264</izz>
                </inertia>
            </inertial>
            <collision name="base_collision">
                <pose frame="">0 0 0.0365 0 0 0 </pose>
                <geometry>
                    <cylinder> 
                        <radius>0.04</radius> 
                        <length>0.073</length>
                    </cylinder>
                </geometry>
            </collision>
            <visual name="base_visual">
                <pose frame=""> 0 0 0 0 0 1.5707 </pose>
                <geometry>
                    <mesh>
                        <uri>model://scoutv2/meshes/os1_64.dae</uri>
                    </mesh>
                </geometry>
            </visual>
        </link>

        <link name="os_sensor_pole">
            <pose frame="">0. -0. 0.24 0 0 0</pose>
            <inertial>
                <mass>0.33</mass>
                <pose frame=""> 0 0 0.365 0 0 0 </pose>
                <inertia>
                    <ixx>0.000241148</ixx>
                    <ixy>0 </ixy>
                    <ixz>0</ixz>
                    <iyy>0.000241148</iyy>
                    <iyz>0</iyz>
                    <izz>0.000264</izz>
                </inertia>
            </inertial>
            <collision name="base_collision">
                <pose frame="">0 0 0.0365 0 0 0 </pose>
                <geometry>
                    <cylinder> 
                        <radius>0.04</radius> 
                        <length>0.073</length>
                    </cylinder>
                </geometry>
            </collision>
            <visual name="base_visual">
                <pose frame="">0 0 0 0 0 0 </pose>
                <geometry>
                    <cylinder>
                        <length>0.46</length>
                        <radius>0.04</radius>
                    </cylinder>
                </geometry>
            </visual>
        </link>




        





        <link name="os_imu">
            <sensor name="os_imu" type="imu">      
                <always_on>1</always_on>
                <update_rate>100</update_rate>
                <visualize>true</visualize>
            </sensor>
        </link>
        <joint name="os_sensor_imu_link_joint" type="fixed">
            <parent> os_sensor </parent>
            <child> os_imu </child>
            <pose frame="">0.006253 -0.011775 0.007645 0 0 0</pose>            
        </joint>


        <link name="os_lidar">
            <sensor name="os_lidar" type="gpu_lidar"> 
                <pose> 0 0 0.5 0 0 0</pose>       
                <update_rate>10</update_rate>        
                
                <lidar>
                    <scan>
                        <horizontal>
                            <samples>512</samples>
                            <resolution>1</resolution>
                            <min_angle>-3.1415926535897931</min_angle>
                            <max_angle>3.1415926535897931</max_angle>
                        </horizontal>
                        <vertical>
                            <samples>128</samples>
                            <resolution>1</resolution>
                            <min_angle>-0.785</min_angle>
                            <max_angle>0.785</max_angle>
                        </vertical>
                    </scan>
                    <range>
                        <min>0.1</min>
                        <max>40</max>
                        <resolution>0.03</resolution>
                    </range>
                </lidar>
                <always_on>1</always_on>
                <visualize>true</visualize>                
            </sensor>        
        </link>
        <joint name="os_sensor_lidar_link_joint" type="fixed">
            <parent> os_sensor </parent>
            <child> os_lidar </child>            
            <pose frame="">0. 0. 0.03618 0 0 0</pose> 
        </joint>



      <plugin name='gz::sim::systems::OdometryPublisher' filename='gz-sim-odometry-publisher-system'>
          <dimensions>3</dimensions>
          <odom_publish_frequency>10.0</odom_publish_frequency>
          <odom_frame> {{ name }}::odom </odom_frame>
          <robot_base_frame> {{ name }} </robot_base_frame>            
      </plugin>



    </model>
</sdf>
